Workbook

Sheet INPUTS - SUMMARY
K1: capex
A2: Power Plant Configuration (INPUTS) | G2: Financial Model Assumptions | K2: 1 | L2: 2 | M2: 3 | N2: 4 | O2: 5
A3: Power Plant Key Cost Scaling Variables | G3: Share of Debt | H3: % | I3: 80 | J3: =I3/100 -> 0.8 | K3: =$B$26/($I$8*(1+$I$14)^K2) -> 484.16683 | L3: =$B$26/($I$8*(1+$I$14)^L2) -> 458.50869
A4: PB Installed Capacity (Gross) | B4: kW | C4: 100000 | G4: Share of Equity | H4: % | I4: 20 | J4: =I4/100 -> 0.2 | K4: Decom
A5: Solar Field Aperture Area (Mirror Area) | B5: m2 | C5: 1639087.1 | G5: Debt Interest Rate | H5: % | I5: 5 | J5: =I5/100 -> 0.05
A6: Thermal Energy Storage Capacity | B6: MWh-th | C6: 8000 | G6: Equity IRR | H6: % | I6: 8 | J6: =I6/100 -> 0.08
A7: Receiver Power (Max Rated) | B7: MW-th | C7: 1456.311 | D7: ** Set to 0 if the CSP plant is a Parabolic Trough (PT) Technology | G7: Lifetime of the plant (Operating period) | H7: years | I7: 30
A8: Tower Height (w/o Receiver) | B8: m | C8: 194.227 | D8: ** Set to 0 if the CSP plant is a Parabolic Trough (PT) Technology | G8: Construction period | H8: years | I8: 2
A9: Electric Heater Thermal Power (Max Rated) | B9: kW-th | C9: 500000 | D9: ** Set to 0 if there is no electric heater installed for hybridization | G9: Decommissioning costs | H9: MUSD | I9: 0
A10: Land Area CSP | B10: m2 | C10: 10535382 | G10: Decommissioning period | H10: years | I10: 0
A11: PV Installed Capacity | B11: Wdc | C11: 1.0200444e+08 | G11: Depreciation | H11: - | I11: -
A12: Battery Pack Power (Max Rated) | B12: MW | C12: 0 | D12: ** Set to 0 if there is no battery pack | G12: Taxes | H12: - | I12: 10 | J12: =I12/100 -> 0.1
A13: Battery Pack Capacity | B13: MWh-e | C13: 0 | D13: ** Set to 0 if there is no battery pack
A14: Battery Annual Generation (for OPEX) | B14: GWh/y | C14: 0 | D14: ** Set to 0 if there is no battery pack | I14: =J4*J6+J3*J5*(1-J12/100) -> 0.05596
A15: Land Area PV | B15: m2 | C15: 39278665
A16: CSP Annual Generation (for OPEX) | B16: GWh/y | C16: 302.52
A17: Distance to Grid | B17: km | C17: 0
A18: Distance to Road | B18: km | C18: 0
A19: Distance to Gas | B19: km | C19: 0 | D19: ** Set to 0 if there is no need for Gas line
A20: Distance to Water | B20: km | C20: 0 | D20: ** Set to 0 if there is no need for water line
A21: Other Component Size | B21: TBD | C21: 0 | D21: ** Set to 0 if ther is no other component to be included, otherwise set also a reference cost in CAPEX and OPEX
A24: DIRECT CAPEX: | B24: =CAPEX!N25 -> 845.05919 | C24: MUSD | D24: =B24/B26*100 -> 82.644628 | E24: % | J24: TOTAL OPEX: | K24: =OPEX!N25 -> 7.2626549 | L24: MUSD
A25: INDIRECT CAPEX: | B25: =CAPEX!N26 -> 177.46243 | C25: MUSD | D25: =B25/B26*100 -> 17.355372 | E25: %
A26: TOTAL CAPEX: | B26: =CAPEX!N27 -> 1022.5216 | C26: MUSD

Sheet CAPEX
A2: Power Plant Inputs (Auto-Update from INPUTS-SUMMARY) | E2: * Light blue fields are reference values. These are site and tech dependent.
A3: Reference Parameters | E3: * If tower technology: SET BOP Reference to 74.8 MUSD
A4: Installed Capacity (Gross) | B4: kW | C4: ='INPUTS - SUMMARY'!C4 -> 100000 | E4: * If tower technology: SET Solar Field Reference Cost to 125 MUSD
A5: ='INPUTS - SUMMARY'!A5 -> Solar Field Aperture Area (Mirror Area) | B5: ='INPUTS - SUMMARY'!B5 -> m2 | C5: ='INPUTS - SUMMARY'!C5 -> 1639087.1 | E5: * If PT technology: SET BOP Reference Cost to 90.2 MUSD
A6: Thermal Energy Storage Capacity | B6: MWh-th | C6: ='INPUTS - SUMMARY'!C6 -> 8000 | E6: * If PT technology: SET Solar Field Reference Cost to 115 MUSD
A7: Receiver Power (Max Rated) | B7: MW-th | C7: ='INPUTS - SUMMARY'!C7 -> 1456.311 | E7: * Set right PV module and tracking costs depending on technology used
A8: Tower Height (w/o Receiver) | B8: m | C8: ='INPUTS - SUMMARY'!C8 -> 194.227 | F8: P-Si = 0.28 $/Wdc
A9: Electric Heater Thermal Power (Max Rated) | B9: kW-th | C9: ='INPUTS - SUMMARY'!C9 -> 500000 | F9: Mono-Si = 0.33 $/Wdc
A10: Land Area | B10: m2 | C10: ='INPUTS - SUMMARY'!C10 -> 10535382 | F10: Thin Film = 0.3 $/Wdc
A11: ='INPUTS - SUMMARY'!A11 -> PV Installed Capacity | B11: ='INPUTS - SUMMARY'!B11 -> Wdc | C11: ='INPUTS - SUMMARY'!C11 -> 1.0200444e+08
A12: Battery Pack Power (Max Rated) | B12: MW | C12: ='INPUTS - SUMMARY'!C12 -> 0
A13: Battery Pack Capacity | B13: MWh-e | C13: ='INPUTS - SUMMARY'!C13 -> 0
A14: Battery Annual Generation (for OPEX) | B14: GWh/y | C14: ='INPUTS - SUMMARY'!C14 -> 0
A15: ='INPUTS - SUMMARY'!A15 -> Land Area PV | B15: ='INPUTS - SUMMARY'!B15 -> m2 | C15: ='INPUTS - SUMMARY'!C15 -> 39278665
A16: ='INPUTS - SUMMARY'!A16 -> CSP Annual Generation (for OPEX) | B16: ='INPUTS - SUMMARY'!B16 -> GWh/y | C16: ='INPUTS - SUMMARY'!C16 -> 302.52
A17: ='INPUTS - SUMMARY'!A17 -> Distance to Grid | B17: ='INPUTS - SUMMARY'!B17 -> km | C17: ='INPUTS - SUMMARY'!C17 -> 0
A18: ='INPUTS - SUMMARY'!A18 -> Distance to Road | B18: ='INPUTS - SUMMARY'!B18 -> km | C18: ='INPUTS - SUMMARY'!C18 -> 0
A19: ='INPUTS - SUMMARY'!A19 -> Distance to Gas | B19: ='INPUTS - SUMMARY'!B19 -> km | C19: ='INPUTS - SUMMARY'!C19 -> 0
A20: ='INPUTS - SUMMARY'!A20 -> Distance to Water | B20: ='INPUTS - SUMMARY'!B20 -> km | C20: ='INPUTS - SUMMARY'!C20 -> 0
A21: ='INPUTS - SUMMARY'!A21 -> Other Component Size | B21: ='INPUTS - SUMMARY'!B21 -> TBD | C21: ='INPUTS - SUMMARY'!C21 -> 0
D23: =SUM(D26:D32)*1.05 -> 460.215
A24: Cost Model Reference Inputs | I24: SUMMARY OF CAPEX RESULTS
A25: Reference Parameters | D25: Reference Cost | F25: Specfic Costs (REF) | M25: DIRECT CAPEX: | N25: =D72 -> 845.05919 | O25: MUSD | P25: =N25/N27*100 -> 82.644628 | Q25: %
A26: ST Installed Capacity (Gross) | B26: kW | C26: 190000 | D26: 87.5 | E26: MUSD | F26: =D26*1000000/(C26) -> 460.52632 | G26: USD/kW | M26: INDIRECT CAPEX: | N26: =D77 -> 177.46243 | O26: MUSD | P26: =N26/N27*100 -> 17.355372 | Q26: %
A27: Balance of Plant (BOP) | B27: kW | C27: 110000 | D27: 74.8 | E27: MUSD | F27: =D27*1000000/(C27) -> 680 | G27: USD/kW | M27: TOTAL CAPEX: | N27: =D78 -> 1022.5216 | O27: MUSD
A28: Solar Field Aperture Area | B28: m2 | C28: 1000000 | D28: 115 | E28: MUSD | F28: =D28*1000000/C28 -> 115 | G28: USD/m2
A29: Thermal Energy Storage Capacity | B29: MWh-th | C29: 3271 | D29: 66 | E29: MUSD | F29: =D29*1000000/(C29*1000) -> 20.177316 | G29: USD/kwh-th
A30: Receiver Power (Max Rated) | B30: MW-th | C30: 565 | D30: 55 | E30: MUSD | F30: =D30*1000000/C30 -> 97345.133 | G30: USD/MW-th
A31: Tower Height (w/o Receiver) | B31: m | C31: 200 | D31: 30 | E31: MUSD | F31: =D31*1000000/C31 -> 150000 | G31: USD/m
A32: Land Area (for CSP Site Preparation) | B32: m2 | C32: 5000000 | D32: 10 | E32: MUSD | F32: =D32*1000000/C32 -> 2 | G32: USD/m2
A33: Electric Heater | B33: kW | C33: 1000000 | D33: 70 | E33: MUSD | F33: =D33*1000000/(C33) -> 70 | G33: USD/kW-t
A34: Grid Connection Costs | B34: km | C34: 1 | D34: 1.5 | E34: MUSD | F34: =D34/C34 -> 1.5 | G34: USD/km
A35: Road Costs | B35: km | C35: 1 | D35: 1.2 | E35: MUSD | F35: =D35/C35 -> 1.2 | G35: USD/km
A36: Gas Pipeline Costs | B36: km | C36: 1 | D36: 1 | E36: MUSD | F36: =D36/C36 -> 1 | G36: USD/km
A37: Water Pipeline Costs | B37: km | C37: 1 | D37: 1 | E37: MUSD | F37: =D37/C37 -> 1 | G37: USD/km
A38: Battery Pack Power (Max Rated) | B38: MW | C38: 1 | D38: 0.225 | E38: MUSD | F38: =D38*1000/C38 -> 225 | G38: USD/kW-e
A39: Battery Pack Capacity (replacement included) | B39: MWh-e | C39: 1 | D39: =0.209*1.45 -> 0.30305 | E39: MUSD | F39: =D39*1000/C39 -> 303.05 | G39: USD/kWh-e
A40: Other Component | B40: - | C40: 1 | D40: 0 | E40: MUSD | F40: =D40/C40 -> 0 | G40: USD/-
A41: PV Modules | B41: Wdc-peak | C41: 1000000 | D41: 0.3 | E41: MUSD | F41: =D41*1000000/C41 -> 0.3 | G41: USD/Wdc-p
A42: PV Inverters | B42: Wdc-peak | C42: 1000000 | D42: 0.1 | E42: MUSD | F42: =D42*1000000/C42 -> 0.1 | G42: USD/Wdc-p
...

Sheet OPEX
A2: Power Plant Inputs (Auto-Update from INPUTS-SUMMARY)
A3: Reference Parameters | E3: * Light blue fields are reference values. These are site and tech dependent.
A4: Installed Capacity (Gross) | B4: kW | C4: ='INPUTS - SUMMARY'!C4 -> 100000 | E4: * Depending on PV tracking, set right OPEX
A5: ='INPUTS - SUMMARY'!A5 -> Solar Field Aperture Area (Mirror Area) | B5: ='INPUTS - SUMMARY'!B5 -> m2 | C5: ='INPUTS - SUMMARY'!C5 -> 1639087.1 | F5: Fixed Trackers | G5: 1 | H5: % of CAPEX
A6: Thermal Energy Storage Capacity | B6: MWh-th | C6: ='INPUTS - SUMMARY'!C6 -> 8000 | F6: Single Axis Tracking | G6: 1.75 | H6: % of CAPEX
A7: Receiver Power (Max Rated) | B7: MW-th | C7: ='INPUTS - SUMMARY'!C7 -> 1456.311
A8: Tower Height (w/o Receiver) | B8: m | C8: ='INPUTS - SUMMARY'!C8 -> 194.227
A9: Electric Heater Thermal Power (Max Rated) | B9: MW-th | C9: ='INPUTS - SUMMARY'!C9 -> 500000
A10: Land Area | B10: m2 | C10: ='INPUTS - SUMMARY'!C10 -> 10535382
A11: ='INPUTS - SUMMARY'!A11 -> PV Installed Capacity | B11: ='INPUTS - SUMMARY'!B11 -> Wdc | C11: ='INPUTS - SUMMARY'!C11 -> 1.0200444e+08
A12: Battery Pack Power (Max Rated) | B12: MW | C12: ='INPUTS - SUMMARY'!C12 -> 0
A13: Battery Pack Capacity | B13: MWh-e | C13: ='INPUTS - SUMMARY'!C13 -> 0
A14: Battery Annual Generation (for OPEX) | B14: GWh/y | C14: ='INPUTS - SUMMARY'!C14 -> 0
A15: ='INPUTS - SUMMARY'!A15 -> Land Area PV | B15: ='INPUTS - SUMMARY'!B15 -> m2 | C15: ='INPUTS - SUMMARY'!C15 -> 39278665
A16: ='INPUTS - SUMMARY'!A16 -> CSP Annual Generation (for OPEX) | B16: ='INPUTS - SUMMARY'!B16 -> GWh/y | C16: ='INPUTS - SUMMARY'!C16 -> 302.52
A17: ='INPUTS - SUMMARY'!A17 -> Distance to Grid | B17: ='INPUTS - SUMMARY'!B17 -> km | C17: ='INPUTS - SUMMARY'!C17 -> 0
A18: ='INPUTS - SUMMARY'!A18 -> Distance to Road | B18: ='INPUTS - SUMMARY'!B18 -> km | C18: ='INPUTS - SUMMARY'!C18 -> 0
A19: ='INPUTS - SUMMARY'!A19 -> Distance to Gas | B19: ='INPUTS - SUMMARY'!B19 -> km | C19: ='INPUTS - SUMMARY'!C19 -> 0
A20: ='INPUTS - SUMMARY'!A20 -> Distance to Water | B20: ='INPUTS - SUMMARY'!B20 -> km | C20: ='INPUTS - SUMMARY'!C20 -> 0
A21: ='INPUTS - SUMMARY'!A21 -> Other Component Size | B21: ='INPUTS - SUMMARY'!B21 -> TBD | C21: ='INPUTS - SUMMARY'!C21 -> 0
A24: Cost Model Reference Inputs | I24: SUMMARY OF OPEX RESULTS
A25: Labor Costs | M25: TOTAL CAPEX: | N25: =D63 -> 7.2626549 | O25: MUSD
A26: Reference Parameters | D26: Reference Cost | F26: Specfic Costs (REF)
A27: Admin/Finance & Management | B27: kW | C27: 110000 | D27: 196100 | E27: USD | F27: =D27/(C27) -> 1.7827273 | G27: USD/kW
A28: Plant Operations Labor | B28: kW | C28: 110000 | D28: 1335600 | E28: USD | F28: =D28/(C28) -> 12.141818 | G28: USD/kW
A29: Plant Maintenance Labor | B29: kW | C29: 110000 | D29: 286200 | E29: USD | F29: =D29/(C29) -> 2.6018182 | G29: USD/kW
A30: Solar Field Maintenance Labor | B30: m2 | C30: 977628 | D30: 212000 | E30: USD | F30: =D30/(C30) -> 0.2168514 | G30: USD/m2
A31: Service Costs
A32: Reference Parameters | D32: Reference Cost | F32: Specfic Costs (REF)
A33: Subcontracted Services | B33: =B16 -> GWh/y | C33: 516 | D33: 227900 | E33: USD | F33: =D33/(C33) -> 441.66667 | G33: USD/GWh/y
A34: =A12 -> Battery Pack Power (Max Rated) | B34: =B12 -> MW | C34: =1/1000 -> 0.001 | D34: 6.9 | E34: USD | F34: =D34/(C34*1000) -> 6.9 | G34: USD/kW
A35: =A14 -> Battery Annual Generation (for OPEX) | B35: =B14 -> GWh/y | C35: =1/1000 -> 0.001 | D35: 2.1 | E35: USD | F35: =D35/(C35*1000) -> 2.1 | G35: USD/MWh/y
A36: Utilitiy Costs
A37: Reference Parameters | D37: Reference Cost | F37: Specfic Costs (REF)
A38: Electricity | B38: kW | C38: 110000 | D38: 1431000 | E38: USD | F38: =D38/(C38) -> 13.009091 | G38: USD/kW
A39: Water | B39: kW | C39: 110000 | D39: 1025232 | E39: USD | F39: =D39/(C39) -> 9.3202909 | G39: USD/kW
A40: Miscellaneous
A41: Reference Parameters | D41: Reference Cost | F41: Specfic Costs (REF)
A42: Other Costs | B42: - | C42: 1 | D42: 0 | E42: USD | F42: =D42/(C42) -> 0 | G42: USD/-
A43: Machinery | B43: kW | C43: 110000 | D43: 216240 | E43: USD | F43: =D43/(C43) -> 1.9658182 | G43: USD/kW
...
